<sdf version='1.7'>
  <model name='makerspet_mini'>
    <link name='base_footprint'>
      <inertial>
        <pose>-0.0065 0 0.042843 0 -0 0</pose>
        <mass>0.7</mass>
        <inertia>
          <ixx>0.000982872</ixx>
          <ixy>1.4408e-20</ixy>
          <ixz>-2.666e-05</ixz>
          <iyy>0.00141365</iyy>
          <iyz>-5.95525e-20</iyz>
          <izz>0.00063588</izz>
        </inertia>
      </inertial>
      <collision name='base_footprint_fixed_joint_lump__base_link_collision'>
        <pose>0 0 0.0309 0 -0 0</pose>
        <geometry>
          <cylinder>
            <length>0.032</length>
            <radius>0.062</radius>
          </cylinder>
        </geometry>
        <surface>
          <contact>
            <ode/>
          </contact>
          <friction>
            <ode/>
          </friction>
        </surface>
      </collision>
      <collision name='base_footprint_fixed_joint_lump__caster_link_collision_1'>
        <pose>-0.051 0 0.0085 0 -0 0</pose>
        <geometry>
          <sphere>
            <radius>0.0085</radius>
          </sphere>
        </geometry>
        <surface>
          <contact>
            <ode/>
          </contact>
          <friction>
            <ode>
              <mu>0.2</mu>
              <mu2>0.2</mu2>
            </ode>
          </friction>
        </surface>
      </collision>
      <collision name='base_footprint_fixed_joint_lump__head_link_collision_2'>
        <pose>0 0 0.0663 0 -0 0</pose>
        <geometry>
          <cylinder>
            <length>0.0388</length>
            <radius>0.062</radius>
          </cylinder>
        </geometry>
        <surface>
          <contact>
            <ode/>
          </contact>
          <friction>
            <ode/>
          </friction>
        </surface>
      </collision>
      <collision name='base_footprint_fixed_joint_lump__base_scan_collision_3'>
        <pose>0 0 0.0853 3.14159 -0 3.14159</pose>
        <geometry>
          <cylinder>
            <length>0.016</length>
            <radius>0.03</radius>
          </cylinder>
        </geometry>
        <surface>
          <contact>
            <ode/>
          </contact>
          <friction>
            <ode/>
          </friction>
        </surface>
      </collision>
      <collision name='base_footprint_fixed_joint_lump__scan_motor_collision_4'>
        <pose>-0.04 0 0.0733 0 0 0</pose>
        <geometry>
          <cylinder>
            <length>0.01</length>
            <radius>0.01</radius>
          </cylinder>
        </geometry>
      </collision>
      <visual name='base_footprint_fixed_joint_lump__base_link_visual'>
        <pose>0 0 0.0309 0 -0 0</pose>
        <geometry>
          <cylinder>
            <length>0.032</length>
            <radius>0.062</radius>
          </cylinder>
        </geometry>
        <material>
          <script>
            <name>Gazebo/White</name>
            <uri>file://media/materials/scripts/gazebo.material</uri>
          </script>
        </material>
      </visual>
      <visual name='base_footprint_fixed_joint_lump__caster_link_visual_1'>
        <pose>-0.051 0 0.0085 0 -0 0</pose>
        <geometry>
          <sphere>
            <radius>0.0085</radius>
          </sphere>
        </geometry>
        <material>
          <script>
            <name>Gazebo/White</name>
            <uri>file://media/materials/scripts/gazebo.material</uri>
          </script>
        </material>
      </visual>
      <visual name='base_footprint_fixed_joint_lump__head_link_visual_2'>
        <pose>0 0 0.0469 0 -0 0</pose>
        <geometry>
          <mesh>
            <scale>0.000124 0.000124 7.8e-05</scale>
            <uri>model://makerspet_mini/mesh/hemisphere.stl</uri>
          </mesh>
        </geometry>
        <material>
          <script>
            <name>Gazebo/Red</name>
            <uri>file://media/materials/scripts/gazebo.material</uri>
          </script>
        </material>
      </visual>
      <visual name='base_footprint_fixed_joint_lump__base_scan_visual_3'>
        <pose>0 0 0.0853 3.14159 -0 3.14159</pose>
        <geometry>
          <cylinder>
            <length>0.016</length>
            <radius>0.03</radius>
          </cylinder>
        </geometry>
        <material>
          <script>
            <name>Gazebo/Black</name>
            <uri>file://media/materials/scripts/gazebo.material</uri>
          </script>
        </material>
      </visual>
      <visual name='base_footprint_fixed_joint_lump__scan_motor_visual_4'>
        <pose>-0.04 0 0.0733 0 0 0</pose>
        <geometry>
          <cylinder>
            <length>0.01</length>
            <radius>0.01</radius>
          </cylinder>
        </geometry>
      </visual>
      <sensor name='laser_scan_sensor' type='ray'>
        <visualize>0</visualize>
        <always_on>1</always_on>
        <update_rate>5</update_rate>
        <ray>
          <scan>
            <horizontal>
              <samples>360</samples>
              <resolution>1</resolution>
              <min_angle>0</min_angle>
              <max_angle>6.28319</max_angle>
            </horizontal>
          </scan>
          <range>
            <min>0.1</min>
            <max>10</max>
            <resolution>0.02</resolution>
          </range>
          <noise>
            <type>gaussian</type>
            <mean>0</mean>
            <stddev>0.01</stddev>
          </noise>
        </ray>
        <plugin name='laser_scan_plugin' filename='libgazebo_ros_ray_sensor.so'>
          <ros>
            <remapping>~/out:=scan</remapping>
          </ros>
          <output_type>sensor_msgs/LaserScan</output_type>
          <frame_name>base_scan</frame_name>
        </plugin>
        <pose>0 0 0.0853 3.14159 -0 3.14159</pose>
      </sensor>
    </link>
    <joint name='wheel_left_joint' type='revolute'>
      <pose relative_to='base_footprint'>0 0.052522 0.0215 -1.5708 0 0</pose>
      <parent>base_footprint</parent>
      <child>wheel_left_link</child>
      <axis>
        <xyz>0 0 1</xyz>
        <limit>
          <lower>-1e+16</lower>
          <upper>1e+16</upper>
        </limit>
        <dynamics>
          <spring_reference>0</spring_reference>
          <spring_stiffness>0</spring_stiffness>
        </dynamics>
      </axis>
    </joint>
    <link name='wheel_left_link'>
      <pose relative_to='wheel_left_joint'>0 0 0 0 -0 0</pose>
      <inertial>
        <pose>0 0 0 1.5708 -0 0</pose>
        <mass>0.05</mass>
        <inertia>
          <ixx>5.90417e-06</ixx>
          <ixy>0</ixy>
          <ixz>0</ixz>
          <iyy>5.90417e-06</iyy>
          <iyz>0</iyz>
          <izz>1.15562e-05</izz>
        </inertia>
      </inertial>
      <collision name='wheel_left_link_collision'>
        <pose>0 0 0 0 -0 0</pose>
        <geometry>
          <cylinder>
            <length>0.0055</length>
            <radius>0.0215</radius>
          </cylinder>
        </geometry>
        <surface>
          <contact>
            <ode/>
          </contact>
          <friction>
            <ode>
              <mu>0.2</mu>
              <mu2>0.2</mu2>
            </ode>
          </friction>
        </surface>
      </collision>
      <visual name='wheel_left_link_visual'>
        <pose>0 0 0 0 -0 0</pose>
        <geometry>
          <cylinder>
            <length>0.0055</length>
            <radius>0.0215</radius>
          </cylinder>
        </geometry>
        <material>
          <script>
            <name>Gazebo/Red</name>
            <uri>file://media/materials/scripts/gazebo.material</uri>
          </script>
        </material>
      </visual>
    </link>
    <joint name='wheel_right_joint' type='revolute'>
      <pose relative_to='base_footprint'>0 -0.052522 0.0215 -1.5708 0 0</pose>
      <parent>base_footprint</parent>
      <child>wheel_right_link</child>
      <axis>
        <xyz>0 0 1</xyz>
        <limit>
          <lower>-1e+16</lower>
          <upper>1e+16</upper>
        </limit>
        <dynamics>
          <spring_reference>0</spring_reference>
          <spring_stiffness>0</spring_stiffness>
        </dynamics>
      </axis>
    </joint>
    <link name='wheel_right_link'>
      <pose relative_to='wheel_right_joint'>0 0 0 0 -0 0</pose>
      <inertial>
        <pose>0 0 0 1.5708 -0 0</pose>
        <mass>0.05</mass>
        <inertia>
          <ixx>5.90417e-06</ixx>
          <ixy>0</ixy>
          <ixz>0</ixz>
          <iyy>5.90417e-06</iyy>
          <iyz>0</iyz>
          <izz>1.15562e-05</izz>
        </inertia>
      </inertial>
      <collision name='wheel_right_link_collision'>
        <pose>0 0 0 0 -0 0</pose>
        <geometry>
          <cylinder>
            <length>0.0055</length>
            <radius>0.0215</radius>
          </cylinder>
        </geometry>
        <surface>
          <contact>
            <ode/>
          </contact>
          <friction>
            <ode>
              <mu>0.2</mu>
              <mu2>0.2</mu2>
            </ode>
          </friction>
        </surface>
      </collision>
      <visual name='wheel_right_link_visual'>
        <pose>0 0 0 0 -0 0</pose>
        <geometry>
          <cylinder>
            <length>0.0055</length>
            <radius>0.0215</radius>
          </cylinder>
        </geometry>
        <material>
          <script>
            <name>Gazebo/Red</name>
            <uri>file://media/materials/scripts/gazebo.material</uri>
          </script>
        </material>
      </visual>
    </link>
    <plugin name='differential_drive_plugin' filename='libgazebo_ros_diff_drive.so'>
      <update_rate>30</update_rate>
      <left_joint>wheel_left_joint</left_joint>
      <right_joint>wheel_right_joint</right_joint>
      <wheel_separation>0.105043</wheel_separation>
      <wheel_diameter>0.043</wheel_diameter>
      <max_wheel_torque>0.171616375</max_wheel_torque>
      <max_wheel_acceleration>1</max_wheel_acceleration>
      <command_topic>cmd_vel</command_topic>
      <publish_odom>1</publish_odom>
      <publish_odom_tf>1</publish_odom_tf>
      <publish_wheel_tf>0</publish_wheel_tf>
      <odometry_topic>odom</odometry_topic>
      <odometry_frame>odom</odometry_frame>
      <robot_base_frame>base_footprint</robot_base_frame>
    </plugin>
    <static>0</static>
    <plugin name='joint_state_plugin' filename='libgazebo_ros_joint_state_publisher.so'>
      <ros>
        <remapping>~/out:=joint_states</remapping>
      </ros>
      <update_rate>30</update_rate>
      <joint_name>wheel_left_joint</joint_name>
      <joint_name>wheel_right_joint</joint_name>
    </plugin>
  </model>
</sdf>
